## 异常分类
##  Exception 和 Error 的区别

在 Java 中，所有的异常和错误都是 `Throwable` 类的子类，`Throwable` 又分为 `Exception`（异常）和 `Error`（错误）。

### `Exception`（异常）

- `Exception` 代表**程序可以处理的错误**。
    
- 它主要是**代码逻辑问题**，或者**外部资源导致的问题**。
    
- `Exception` 可以使用 `try-catch` 捕获，或者 `throws` 让调用者处理。
    
- **主要类别**：
    
    - **运行时异常（**`**RuntimeException**`**）**：如 `NullPointerException`、`IndexOutOfBoundsException`。
        
    - **受检异常（Checked Exception）**：如 `IOException`、`SQLException`。
        

#### 示例

```java
public class ExceptionExample {
    public static void main(String[] args) {
        try {
            int[] arr = new int[5];
            System.out.println(arr[10]); // 这里会抛出 IndexOutOfBoundsException
        } catch (ArrayIndexOutOfBoundsException e) {
            System.out.println("数组索引越界异常！");
        }
    }
}
```

### `Error`（错误）

- `Error` 代表**程序无法处理的严重问题**。
    
- 一般由**JVM 运行时问题**导致，如内存溢出、栈溢出。
    
- **通常不建议捕获** `Error`，因为它表示系统级问题，无法恢复。
    
- **主要类别**：
    
    - `OutOfMemoryError`（内存溢出错误）
        
    - `StackOverflowError`（栈溢出错误）
        
    - `ThreadDeath`（线程被强制终止）
        
    - `AssertionError`（断言错误）
        

#### 示例

```java
public class ErrorExample {
    public static void recursiveMethod() {
        recursiveMethod(); // 无限递归调用，最终导致栈溢出
    }
    
    public static void main(String[] args) {
        recursiveMethod();
    }
}
```

**运行结果**（会抛出 `StackOverflowError`）：

```
Exception in thread "main" java.lang.StackOverflowError
    at ErrorExample.recursiveMethod(ErrorExample.java:3)
    at ErrorExample.recursiveMethod(ErrorExample.java:3)
    ...
```

### `Exception` vs `Error` 对比

|             |                                      |                                         |
| ----------- | ------------------------------------ | --------------------------------------- |
| 比较项         | `Exception`                          | `Error`                                 |
| **代表的错误类型** | 程序可处理的错误                             | JVM 运行时严重错误                             |
| **是否可恢复**   | 是，通常可以用 `try-catch` 处理               | 否，一般不应捕获                                |
| **主要示例**    | `IOException`、`NullPointerException` | `OutOfMemoryError`、`StackOverflowError` |
| **是否影响程序**  | 可以继续运行                               | 通常程序崩溃                                  |
## 异常处理
### 1. `throw` 和 `throws` 的区别

#### `throw`（抛出异常）

- `throw` 关键字用于**方法或代码块**中主动抛出异常。
    
- 只能抛出一个异常对象，通常是 `new` 出来的异常。
    
- 一旦执行 `throw`，后续代码不会执行，直接跳转到异常处理流程。
    

##### 示例

```java
public class ThrowExample {
    public static void main(String[] args) {
        int age = 15;
        if (age < 18) {
            throw new IllegalArgumentException("未满18岁，不允许注册！");
        }
        System.out.println("注册成功！");
    }
}
```

#### `throws`（声明异常）

- `throws` 关键字用于**方法声明**，表示该方法可能会抛出异常，让调用者处理。
    
- 不抛出异常，而是**提醒调用者**方法可能会抛出异常。
    
- `throws` 后面可以声明多个异常，用逗号分隔。
    

##### 示例

```
import java.io.*;

public class ThrowsExample {
    public static void readFile() throws IOException {
        FileReader file = new FileReader("test.txt");
        file.read();
        file.close();
    }

    public static void main(String[] args) {
        try {
            readFile();
        } catch (IOException e) {
            System.out.println("文件未找到！");
        }
    }
}
```

#### `throw` vs `throws` 对比

|比较项|`throw`|`throws`|
|---|---|---|
|**作用**|在方法或代码块内部抛出异常对象|在方法声明处声明可能抛出的异常|
|**位置**|方法体内部|方法签名（声明）处|
|**抛出方式**|只能抛出**一个**异常对象|可以声明**多个**异常，用 `,` 分隔|
|**是否终止执行**|一旦执行 `throw`，代码立即终止|`throws` 只是声明，方法内部是否抛出异常取决于实际代码|

---

### 2. 为什么 IDEA 要求 `throws`？

当调用的库函数方法声明了 `throws`（抛出受检异常），你有两种选择：

1. **捕获并处理异常（**`**try-catch**`**）**
    

```
try {
    readFile();
} catch (IOException e) {
    System.out.println("发生 IO 异常：" + e.getMessage());
}
```

1. **继续抛出异常（**`**throws**`**）**
    

```
public static void main(String[] args) throws IOException {
    readFile(); // IDEA 不会报错，因为异常被继续抛出
}
```

如果不处理，IDEA 会提示你必须 `throws`，以确保调用者知道可能发生异常。

---

### 3. 如果 `throws` 了异常，真的发生异常会怎么样？

当方法声明 `throws` 异常，而调用者没有 `try-catch` 处理，异常会沿着方法调用链向上传递，最终导致程序崩溃。

#### 示例：未捕获异常导致程序崩溃

```
public static void main(String[] args) throws IOException {
    readFile(); // 这里会抛出 IOException
}
```

**运行结果（如果** `**test.txt**` **不存在）：**

```
Exception in thread "main" java.io.FileNotFoundException: test.txt (系统找不到指定的文件。)
    at java.base/java.io.FileInputStream.open0(Native Method)
    at java.base/java.io.FileInputStream.open(FileInputStream.java:211)
    at java.base/java.io.FileReader.<init>(FileReader.java:75)
    at Example.readFile(Example.java:11)
    at Example.main(Example.java:6)
```

> **解释**：
> 
> - `readFile()` 方法抛出了 `IOException`。
>     
> - `main()` 也 `throws` 了异常，而没有 `try-catch` 处理。
>     
> - JVM 发现异常没有被捕获，直接终止程序，并打印异常的调用栈。
>     

---

### 4. `try-catch` vs `throws` 使用建议

|                  |                                    |
| ---------------- | ---------------------------------- |
| 方式               | 发生异常时的行为                           |
| `try-catch` 处理异常 | 程序不会崩溃，异常被捕获并处理                    |
| `throws` 声明异常    | 异常会继续向上抛出，如果最终没有 `try-catch`，程序会崩溃 |

#### **最佳实践**

- **如果方法可以妥善处理异常**（如打印日志、提供默认值等），使用 `try-catch`。
    
- **如果方法不能处理异常，而调用者可能有更好的处理方式**，使用 `throws` 让调用者决定如何处理。

### 5. `try-catch-finally` 语句注意事项

#### 1. `try-catch-finally` 执行顺序

- `try` 代码块先执行。
    
- **如果发生异常**，寻找匹配的 `catch` 代码块执行。
    
- **如果** `**try**` **没有异常**，跳过 `catch`，直接执行 `finally`（如果有）。
    
- `**finally**` **总会执行**，即使 `try` 里有 `return`，但 `System.exit(0);` 例外。
    

##### 示例

```java
public class TryCatchExample {
    public static void main(String[] args) {
        try {
            System.out.println("1. 进入 try 块");
            int result = 10 / 0; // 发生异常
        } catch (ArithmeticException e) {
            System.out.println("2. 进入 catch 块");
        } finally {
            System.out.println("3. 进入 finally 块");
        }
        System.out.println("4. 结束程序");
    }
}
```

**输出**

```java
1. 进入 try 块
2. 进入 catch 块
3. 进入 finally 块
4. 结束程序
```

---

#### 2. `catch` 只会执行一个匹配的异常

- 只执行**第一个匹配的** `**catch**`，后面的 `catch` 代码块不会再执行。
    
- `Exception` 作为通配符时，**应放在最后**，否则会导致编译错误。
    

##### 示例

```java
try {
    int[] arr = new int[5];
    System.out.println(arr[10]); // 发生 ArrayIndexOutOfBoundsException
} catch (ArithmeticException e) {
    System.out.println("捕获 ArithmeticException");
} catch (ArrayIndexOutOfBoundsException e) {
    System.out.println("捕获 ArrayIndexOutOfBoundsException");
} catch (Exception e) {
    System.out.println("捕获通用 Exception");
}
```

**输出**

```
捕获 ArrayIndexOutOfBoundsException
```

---

#### 3. `finally` 在 `return` 之前执行

- **即使** `**try**` **里有** `**return**`**，**`**finally**` **仍然会执行**。
    
- **避免在** `**finally**` **中使用** `**return**`**，会覆盖** `**try**` **的返回值**。
    

##### 示例

```java
public static int test() {
    try {
        return 10;
    } finally {
        System.out.println("执行 finally");
    }
}

public static void main(String[] args) {
    System.out.println("返回值：" + test());
}
```

**输出**

```
执行 finally
返回值：10
```

##### `finally` 影响返回值

```java
public static int test() {
    try {
        return 10;
    } finally {
        return 20; // 覆盖 try 的 return 10
    }
}
```

**输出**

```
返回值：20
```

⚠️ 避免在 `finally` 里写 `return`，会覆盖 `try` 的返回值！

---

#### 4. `System.exit(0);` 会跳过 `finally`

```java
try {
    System.out.println("1. 进入 try 块");
    System.exit(0);  // 直接退出程序
} finally {
    System.out.println("2. 进入 finally 块");  // 不会执行！
}
```

**输出**

```
1. 进入 try 块
```

**解释**

- `System.exit(0);` 直接终止 JVM，`finally` **不会执行**。
    

---

#### 5. `try-catch` 使用建议

| 方式                     | 说明                                  |
| ---------------------- | ----------------------------------- |
| `try-catch` 处理异常       | **推荐**，可避免程序崩溃                      |
| `finally` 代码块          | **适用于资源释放**（如关闭数据库连接、文件流等）          |
| `throws` 声明异常          | **适用于让调用者处理异常**                     |
| `catch` 的顺序            | **子类异常放前面，**`**Exception**` **放最后** |
| `finally` 里不要 `return` | **避免覆盖** `**try**` **的返回值**         |